Traceback (most recent call last):
  File "/usr/local/lib/python3.9/site-packages/jupyter_cache/executors/utils.py", line 51, in single_nb_execution
    executenb(
  File "/usr/local/lib/python3.9/site-packages/nbclient/client.py", line 1093, in execute
    return NotebookClient(nb=nb, resources=resources, km=km, **kwargs).execute()
  File "/usr/local/lib/python3.9/site-packages/nbclient/util.py", line 84, in wrapped
    return just_run(coro(*args, **kwargs))
  File "/usr/local/lib/python3.9/site-packages/nbclient/util.py", line 62, in just_run
    return loop.run_until_complete(coro)
  File "/usr/local/Cellar/python@3.9/3.9.19/Frameworks/Python.framework/Versions/3.9/lib/python3.9/asyncio/base_events.py", line 647, in run_until_complete
    return future.result()
  File "/usr/local/lib/python3.9/site-packages/nbclient/client.py", line 559, in async_execute
    await self.async_execute_cell(
  File "/usr/local/lib/python3.9/site-packages/nbclient/client.py", line 854, in async_execute_cell
    self._check_raise_for_error(cell, exec_reply)
  File "/usr/local/lib/python3.9/site-packages/nbclient/client.py", line 756, in _check_raise_for_error
    raise CellExecutionError.from_cell_and_msg(cell, exec_reply_content)
nbclient.exceptions.CellExecutionError: An error occurred while executing the following cell:
------------------
import sys
!{sys.executable} -m pip install --upgrade scikit-image
from skimage import measure
x, y, z = np.mgrid[-1:1:31j, -1:1:31j, -1:1:31j]
vol = x**2 - y**2 + 4 * z
iso_val=0.0
verts, faces, _, _ = measure.marching_cubes(vol, iso_val, spacing=(0.1, 0.1, 0.1))

fig = plt.figure()
ax = fig.add_subplot(111, projection='3d')
ax.plot_trisurf(verts[:, 0], verts[:,1], faces, verts[:, 2], cmap='Spectral',
                lw=1)
plt.show()
------------------

[0;31m---------------------------------------------------------------------------[0m
[0;31mValueError[0m                                Traceback (most recent call last)
Cell [0;32mIn[19], line 3[0m
[1;32m      1[0m [38;5;28;01mimport[39;00m [38;5;21;01msys[39;00m
[1;32m      2[0m get_ipython()[38;5;241m.[39msystem([38;5;124m'[39m[38;5;132;01m{sys.executable}[39;00m[38;5;124m -m pip install --upgrade scikit-image[39m[38;5;124m'[39m)
[0;32m----> 3[0m [38;5;28;01mfrom[39;00m [38;5;21;01mskimage[39;00m [38;5;28;01mimport[39;00m measure
[1;32m      4[0m x, y, z [38;5;241m=[39m np[38;5;241m.[39mmgrid[[38;5;241m-[39m[38;5;241m1[39m:[38;5;241m1[39m:[38;5;241m31[39mj, [38;5;241m-[39m[38;5;241m1[39m:[38;5;241m1[39m:[38;5;241m31[39mj, [38;5;241m-[39m[38;5;241m1[39m:[38;5;241m1[39m:[38;5;241m31[39mj]
[1;32m      5[0m vol [38;5;241m=[39m x[38;5;241m*[39m[38;5;241m*[39m[38;5;241m2[39m [38;5;241m-[39m y[38;5;241m*[39m[38;5;241m*[39m[38;5;241m2[39m [38;5;241m+[39m [38;5;241m4[39m [38;5;241m*[39m z

File [0;32m/usr/local/lib/python3.9/site-packages/skimage/__init__.py:122[0m
[1;32m    118[0m     [38;5;66;03m# We are not importing the rest of the scikit during the build[39;00m
[1;32m    119[0m     [38;5;66;03m# process, as it may not be compiled yet[39;00m
[1;32m    120[0m [38;5;28;01melse[39;00m:
[1;32m    121[0m     [38;5;28;01mtry[39;00m:
[0;32m--> 122[0m         [38;5;28;01mfrom[39;00m [38;5;21;01m.[39;00m[38;5;21;01m_shared[39;00m [38;5;28;01mimport[39;00m geometry
[1;32m    123[0m         [38;5;28;01mdel[39;00m geometry
[1;32m    124[0m     [38;5;28;01mexcept[39;00m [38;5;167;01mImportError[39;00m [38;5;28;01mas[39;00m e:

File [0;32mgeometry.pyx:1[0m, in [0;36minit skimage._shared.geometry[0;34m()[0m

[0;31mValueError[0m: numpy.ndarray size changed, may indicate binary incompatibility. Expected 96 from C header, got 88 from PyObject
ValueError: numpy.ndarray size changed, may indicate binary incompatibility. Expected 96 from C header, got 88 from PyObject

